Workbook

Sheet Kit_Solaire
A1: Ref LM | B1: Produit | C1: Prix de vente | D1: Quantiter | E1: Promo | F1: Remise peso | I1: Puissance théorique Totale | L1: Eco réaliser Total | N1: Eco moins Achat
A2: 85578551 | B2: Kit Solaire Master 370 Wcrete | C2: 579 | D2: 1 | E2: 360.48 | F2: -0.38 | I2: =(3*0.37)+3 -> 4.11 | J2: KWC | L2: =D10+D11+D12+D13+D14+D15+D16+D17 -> 2316.3827 | N2: =L2-L26 -> -3889.2673
A3: 85578552 | B3: Kit Solaire Exention 370 Wcrete | C3: 559 | D3: 2 | E3: =807.76/2 -> 403.88 | F3: -0.28
A4: 86147168 | B4: Prise Hombli Smart plug | C4: 29.9 | D4: 1 | E4: 25.41 | F4: -0.15 | G4: Date de mise en Service
C5: =C2+(C3*2)+C4 -> 1726.9 | D5: -0.31 | E5: =E2+(E3*2)+E4 -> 1193.65 | F5: =E5 -> 1193.65 | G5: 45054
B9: Amortisment | C9: eco theorique | D9: Eco réaliser anuelle | E9: Kwh Prod | F9: Reste a amortir | G9: Amorti Total en % | H9: Reste a amortir en % | I9: Kwh Injecter/Année | L9: Revente Facturé EDF | N9: Revente anuelle théorique | O9: KWH Facturé
B10: 2023 | C10: =SUM(Tableau3[Economi theorique]) -> 191.19217 | D10: =C10-(I10*J10) -> 180.70047 | E10: =Global!G15 -> 904.28 | F10: =L26-D10 -> 6024.9495 | G10: =D10/L26 -> 0.029118702 | H10: =F10/L26 -> 0.9708813 | I10: 50 | J10: =AVERAGE(Tableau3[Prix du KWH Sans abonement Prix Econmiser du KWH Solaire Produit]) -> 0.20983389 | K10: =I10*J10 -> 10.491695 | L10: 0 | N10: 0
B11: 2024 | C11: =SUM(Tableau37[Economi theorique]) -> 430.56206 | D11: =C11-(I11*J11) -> 304.41212 | E11: =Global!G31 -> 1709.17 | F11: =F10-D11 -> 5720.5374 | G11: =D11/L26+G10 -> 0.078172729 | H11: =F11/L26 -> 0.92182727 | I11: =556-I10 -> 506 | J11: =AVERAGE(Tableau37[Prix du KWH Sans abonement Prix Econmiser du KWH Solaire Produit]) -> 0.24930817 | K11: =I11*J11 -> 126.14993 | L11: 0 | N11: 0
B12: 2025 | C12: =SUM(Tableau378[Economi theorique]) -> 1358.947 | D12: =C12-(I12*J12)+L12 -> 968.18972 | E12: =Global!G47 -> 5120.12 | F12: =F11-D12 -> 4752.3477 | G12: =D12/L26+G11 -> 0.23419018 | H12: =F12/L26 -> 0.76580982 | I12: =3430-(I11+I10) -> 2874 | J12: =AVERAGE(Tableau378[Prix du KWH Sans abonement Prix Econmiser du KWH Solaire Produit]) -> 0.26538179 | K12: =(I12*J12)-L12 -> 390.75725 | L12: =1151.95-780 -> 371.95 | N12: =I12*F28 -> 366.7224 | O12: 2915
B13: 2026 | C13: =SUM(Tableau3789[Economi theorique]) -> 1238.1232 | D13: =C13-(I13*J13)+L13 -> 863.08042 | E13: =Global!G63 -> 4558.98 | F13: =F12-D13 -> 3889.2673 | G13: =D13/L26+G12 -> 0.37326996 | H13: =F13/L26 -> 0.62673004 | I13: =6038-I12-I11-I10 -> 2608 | J13: =AVERAGE(Tableau3789[Prix du KWH Sans abonement Prix Econmiser du KWH Solaire Produit]) -> 0.27468282 | K13: =(I13*J13)-L13 -> 375.0428 | L13: =O13*F28 -> 341.33 | O13: =I18-(448+O12) -> 2675
B14: 2027
B15: 2028
B16: 2029
B17: 2030
I18: =SUM(I10:I17) -> 6038 | L18: Facture TT EDF
I19: KWH TT Injecter | L19: =L12+L13+L14+L15+L16+L17 -> 713.28
A25: Facture | B25: Produit | C25: W/Unit | D25: KWC TT | E25: Prix ttc | F25: Prime | G25: TTC moins Prime | H25: Date mise en Service | L25: Investisment Totale
A26: 202406-296 | B26: Photovolataîque V4,02 mod Dualsun bifacial | C26: 500W | D26: 3 KWC | E26: =6320-528 -> 5792 | F26: =260*3 -> 780 | G26: =E26-F26 -> 5012 | H26: 45582 | L26: =G26+F5 -> 6205.65
F27: Revente KWH
F28: 0.1276

Sheet Global
A1: 2023 | B1: KWH Moyenne jour | C1: KWH Total | D1: Moyenne Jour € | E1: Total € | F1: Production Solaire /KWH Moyenne Jour | G1: Total Prod | H1: Prix du KWH Conso+Abo/KWH | I1: Economi theorique | J1: Reste a amortire | K1: Prix du KWH Sans abonement Prix Econmiser du KWH Solaire Produit
A2: Janvier | B2: =AVERAGE('2023'!$C$3:$C$33) -> 17.478387 | C2: =SUM('2023'!$C$3:$C$33) -> 541.83 | D2: =AVERAGE('2023'!$F$3:$F$33) -> 4.0558065 | E2: =SUM('2023'!$F$3:$F$33) -> 125.73 | F2: 0 | G2: =SUM('2023'!$G$3:$G$33) -> 0 | H2: =E2/C2 -> 0.23204695 | I2: =G2*K2 -> 0 | J2: =Kit_Solaire!F5-Global!I2 -> 1193.65
A3: Fevrier | B3: =AVERAGE('2023'!$C$34:$C$61) -> 15.966071 | C3: =SUM('2023'!$C$34:$C$61) -> 447.05 | D3: =AVERAGE('2023'!$F$34:$F$61) -> 3.8007143 | E3: =SUM('2023'!$F$34:$F$61) -> 106.42 | F3: 0 | G3: =SUM('2023'!$G$34:$G$61) -> 0 | H3: =E3/C3 -> 0.23804944 | I3: =G3*K3 -> 0 | J3: =J2-I3 -> 1193.65
A4: Mars | B4: =AVERAGE('2023'!$C$62:$C$92) -> 13.452581 | C4: =SUM('2023'!$C$62:$C$92) -> 417.03 | D4: =AVERAGE('2023'!$F$62:$F$92) -> 3.2296774 | E4: =SUM('2023'!$F$62:$F$92) -> 100.12 | F4: 0 | G4: =SUM('2023'!$G$62:$G$92) -> 0 | H4: =E4/C4 -> 0.24007865 | I4: =G4*K4 -> 0 | J4: =J3-I4 -> 1193.65
A5: Avril | B5: =AVERAGE('2023'!$C$93:$C$122) -> 13.560667 | C5: =SUM('2023'!$C$93:$C$122) -> 406.82 | D5: =AVERAGE('2023'!$F$93:$F$122) -> 3.208 | E5: =SUM('2023'!$F$93:$F$122) -> 96.24 | F5: 0 | G5: =SUM('2023'!$G$93:$G$122) -> 0 | H5: =E5/C5 -> 0.23656654 | I5: =G5*K5 -> 0 | J5: =J4-I5 -> 1193.65
A6: Mai | B6: =AVERAGE('2023'!$C$123:$C$153) -> 20.549677 | C6: =SUM('2023'!$C$123:$C$153) -> 637.04 | D6: =AVERAGE('2023'!$F$123:$F$153) -> 4.5612903 | E6: =SUM('2023'!$F$123:$F$153) -> 141.4 | F6: =AVERAGE('2023'!$G$123:$G$153) -> 4.4166667 | G6: =SUM('2023'!$G$123:$G$153) -> 106 | H6: =E6/C6 -> 0.22196408 | I6: =G6*K6 -> 21.4649 | J6: =J5-I6 -> 1172.1851 | K6: =SUM('2023'!$D$123:$D$153)/C6 -> 0.20249906
A7: Juin | B7: =AVERAGE('2023'!$C$154:$C$183) -> 10.078333 | C7: =SUM('2023'!$C$154:$C$183) -> 302.35 | D7: =AVERAGE('2023'!$F$154:$F$183) -> 2.5786667 | E7: =SUM('2023'!$F$154:$F$183) -> 77.36 | F7: =AVERAGE('2023'!$G$154:$G$183) -> 5.399 | G7: =SUM('2023'!$G$154:$G$183) -> 161.97 | H7: =E7/C7 -> 0.25586241 | I7: =G7*K7 -> 35.013591 | J7: =J6-I7 -> 1137.1715 | K7: =SUM('2023'!$D$154:$D$183)/C7 -> 0.21617331
A8: Juillet | B8: =AVERAGE('2023'!$C$184:$C$214) -> 11.411935 | C8: =SUM('2023'!$C$184:$C$214) -> 353.77 | D8: =AVERAGE('2023'!$F$184:$F$214) -> 2.8445161 | E8: =SUM('2023'!$F$184:$F$214) -> 88.18 | F8: =AVERAGE('2023'!$G$184:$G$214) -> 5.8035484 | G8: =SUM('2023'!$G$184:$G$214) -> 179.91 | H8: =E8/C8 -> 0.24925799 | I8: =G8*K8 -> 38.537976 | J8: =J7-I8 -> 1098.6335 | K8: =SUM('2023'!$D$184:$D$214)/C8 -> 0.21420697
A9: Août | B9: =AVERAGE('2023'!$C$215:$C$245) -> 12.496774 | C9: =SUM('2023'!$C$215:$C$245) -> 387.4 | D9: =AVERAGE('2023'!$F$215:$F$245) -> 3.0496774 | E9: =SUM('2023'!$F$215:$F$245) -> 94.54 | F9: =AVERAGE('2023'!$G$215:$G$245) -> 5.1006452 | G9: =SUM('2023'!$G$215:$G$245) -> 158.12 | H9: =E9/C9 -> 0.24403717 | I9: =G9*K9 -> 33.526011 | J9: =J8-I9 -> 1065.1075 | K9: =SUM('2023'!$D$215:$D$245)/C9 -> 0.21202891
A10: Septembre | B10: =AVERAGE('2023'!$C$246:$C$275) -> 11.298333 | C10: =SUM('2023'!$C$246:$C$275) -> 338.95 | D10: =AVERAGE('2023'!$F$246:$F$275) -> 2.8016667 | E10: =SUM('2023'!$F$246:$F$275) -> 84.05 | F10: =AVERAGE('2023'!$G$246:$G$275) -> 4.5493333 | G10: =SUM('2023'!$G$246:$G$275) -> 136.48 | H10: =E10/C10 -> 0.24797168 | I10: =G10*K10 -> 29.011311 | J10: =J9-I10 -> 1036.0962 | K10: =SUM('2023'!$D$246:$D$275)/C10 -> 0.21256823
A11: Octobre | B11: =AVERAGE('2023'!$C$276:$C$306) -> 10.137742 | C11: =SUM('2023'!$C$276:$C$306) -> 314.27 | D11: =AVERAGE('2023'!$F$276:$F$306) -> 2.5283871 | E11: =SUM('2023'!$F$276:$F$306) -> 78.38 | F11: =AVERAGE('2023'!$G$276:$G$306) -> 2.8816129 | G11: =SUM('2023'!$G$276:$G$306) -> 89.33 | H11: =E11/C11 -> 0.24940338 | I11: =G11*K11 -> 18.754553 | J11: =J10-I11 -> 1017.3417 | K11: =SUM('2023'!$D$276:$D$306)/C11 -> 0.20994686
A12: Novembre | B12: =AVERAGE('2023'!$C$307:$C$336) -> 12.218333 | C12: =SUM('2023'!$C$307:$C$336) -> 366.55 | D12: =AVERAGE('2023'!$F$307:$F$336) -> 2.895 | E12: =SUM('2023'!$F$307:$F$336) -> 86.85 | F12: =AVERAGE('2023'!$G$307:$G$336) -> 1.4156667 | G12: =SUM('2023'!$G$307:$G$336) -> 42.47 | H12: =E12/C12 -> 0.23693903 | I12: =G12*K12 -> 8.6724308 | J12: =J11-I12 -> 1008.6692 | K12: =SUM('2023'!$D$307:$D$336)/C12 -> 0.20420134
A13: Décembre | B13: =AVERAGE('2023'!$C$337:$C$367) -> 14.319677 | C13: =SUM('2023'!$C$337:$C$367) -> 443.91 | D13: =AVERAGE('2023'!$F$337:$F$367) -> 3.3648387 | E13: =SUM('2023'!$F$337:$F$367) -> 104.31 | F13: =AVERAGE('2023'!$G$337:$G$367) -> 0.96774194 | G13: =SUM('2023'!$G$337:$G$367) -> 30 | H13: =E13/C13 -> 0.23498006 | I13: =G13*K13 -> 6.2113942 | J13: =J12-I13 -> 1002.4578 | K13: =SUM('2023'!$D$337:$D$367)/C13 -> 0.20704647
B14: KWH J | C14: KWH Tt | D14: Moy / Mois | E14: Total | G14: Total | M14: Solaire utiliser | N14: eco
B15: =C15/365 -> 13.58074 | C15: =C2+C3+C4+C5+C6+C7+C8+C9+C10+C11+C12+C13 -> 4956.97 | D15: =E15/12 -> 98.631667 | E15: =E2+E3+E4+E5+E6+E7+E8+E9+E10+E11+E12+E13 -> 1183.58 | G15: =SUM(G6:G13) -> 904.28 | M15: =G15-Global!I10 -> 875.26869 | N15: =M15*Kit_Solaire!J10 -> 183.66104
A17: 2024 | B17: KWH Moyenne jour | C17: KWH Total | D17: Moyenne Jour € | E17: Total € | F17: Production Solaire /KWH Moyenne Jour | G17: Total Prod | H17: Prix du KWH Conso+Abo/KWH | I17: Economi theorique | J17: Reste a amortire | K17: Prix du KWH Sans abonement Prix Econmiser du KWH Solaire Produit
A18: Janvier | B18: =AVERAGE('2024'!$C$3:$C$33) -> 14.15129 | C18: =SUM('2024'!$C$3:$C$33) -> 438.69 | D18: =AVERAGE('2024'!$F$3:$F$33) -> 3.3216129 | E18: =SUM('2024'!$F$3:$F$33) -> 102.97 | F18: =AVERAGE('2024'!$G$3:$G$33) -> 1.2541935 | G18: =SUM('2024'!$G$3:$G$33) -> 38.88 | H18: =E18/C18 -> 0.23472156 | I18: =G18*K18 -> 8.0269931 | J18: =J13-Tableau37[[#This Row],[Economi theorique]] -> 994.43084 | K18: =SUM('2024'!$D$3:$D$33)/C18 -> 0.20645558
A19: Fevrier | B19: =AVERAGE('2024'!$C$34:$C$62) -> 13.664138 | C19: =SUM('2024'!$C$34:$C$62) -> 396.26 | D19: =AVERAGE('2024'!$F$34:$F$62) -> 3.8468966 | E19: =SUM('2024'!$F$34:$F$62) -> 111.56 | F19: =AVERAGE('2024'!$G$34:$G$62) -> 1.8148276 | G19: =SUM('2024'!$G$34:$G$62) -> 52.63 | H19: =E19/C19 -> 0.28153233 | I19: =G19*K19 -> 13.276371 | J19: =J18-Tableau37[[#This Row],[Economi theorique]] -> 981.15447 | K19: =SUM('2024'!$D$34:$D$62)/C19 -> 0.25225862
A20: Mars | B20: =AVERAGE('2024'!$C$63:$C$93) -> 11.438387 | C20: =SUM('2024'!$C$63:$C$93) -> 354.59 | D20: =AVERAGE('2024'!$F$63:$F$93) -> 3.173871 | E20: =SUM('2024'!$F$63:$F$93) -> 98.39 | F20: =AVERAGE('2024'!$G$63:$G$93) -> 3.5819355 | G20: =SUM('2024'!$G$63:$G$93) -> 111.04 | H20: =E20/C20 -> 0.27747539 | I20: =G20*K20 -> 25.863091 | J20: =J19-Tableau37[[#This Row],[Economi theorique]] -> 955.29138 | K20: =SUM('2024'!$D$63:$D$92)/C20 -> 0.23291689
A21: Avril | B21: =AVERAGE('2024'!$C$94:$C$123) -> 9.565 | C21: =SUM('2024'!$C$94:$C$123) -> 286.95 | D21: =AVERAGE('2024'!$F$94:$F$123) -> 2.7993333 | E21: =SUM('2024'!$F$94:$F$123) -> 83.98 | F21: =AVERAGE('2024'!$G$94:$G$123) -> 4.5416667 | G21: =SUM('2024'!$G$94:$G$123) -> 136.25 | H21: =E21/C21 -> 0.29266423 | I21: =G21*K21 -> 34.177644 | J21: =J20-Tableau37[[#This Row],[Economi theorique]] -> 921.11373 | K21: =SUM('2024'!$D$94:$D$123)/C21 -> 0.25084509
A22: Mai | B22: =AVERAGE('2024'!$C$124:$C$154) -> 8.386129 | C22: =SUM('2024'!$C$124:$C$154) -> 259.97 | D22: =AVERAGE('2024'!$F$124:$F$154) -> 2.5732258 | E22: =SUM('2024'!$F$124:$F$154) -> 79.77 | F22: =AVERAGE('2024'!$G$124:$G$154) -> 4.636129 | G22: =SUM('2024'!$G$124:$G$154) -> 143.72 | H22: =E22/C22 -> 0.3068431 | I22: =G22*K22 -> 37.244361 | J22: =J21-Tableau37[[#This Row],[Economi theorique]] -> 883.86937 | K22: =SUM('2024'!$D$124:$D$154)/C22 -> 0.25914529
A23: Juin | B23: =AVERAGE('2024'!$C$155:$C$184) -> 9.5536667 | C23: =SUM('2024'!$C$155:$C$184) -> 286.61 | D23: =AVERAGE('2024'!$F$155:$F$184) -> 2.9186667 | E23: =SUM('2024'!$F$155:$F$184) -> 87.56 | F23: =AVERAGE('2024'!$G$155:$G$184) -> 5.1673333 | G23: =SUM('2024'!$G$155:$G$184) -> 155.02 | H23: =E23/C23 -> 0.30550225 | I23: =G23*K23 -> 40.868467 | J23: =J22-Tableau37[[#This Row],[Economi theorique]] -> 843.00091 | K23: =SUM('2024'!$D$155:$D$184)/C23 -> 0.26363351
A24: Juillet | B24: =AVERAGE('2024'!$C$185:$C$215) -> 10.115806 | C24: =SUM('2024'!$C$185:$C$215) -> 313.59 | D24: =AVERAGE('2024'!$F$185:$F$215) -> 3.0651613 | E24: =SUM('2024'!$F$185:$F$215) -> 95.02 | F24: =AVERAGE('2024'!$G$185:$G$215) -> 5.7870968 | G24: =SUM('2024'!$G$185:$G$215) -> 179.4 | H24: =E24/C24 -> 0.30300711 | I24: =G24*K24 -> 45.852578 | J24: =J23-Tableau37[[#This Row],[Economi theorique]] -> 797.14833 | K24: =SUM('2024'!$D$185:$D$214)/C24 -> 0.25558851
A25: Août | B25: =AVERAGE('2024'!$C$216:$C$246) -> 10.943871 | C25: =SUM('2024'!$C$216:$C$246) -> 339.26 | D25: =AVERAGE('2024'!$F$216:$F$246) -> 3.2916129 | E25: =SUM('2024'!$F$216:$F$246) -> 102.04 | F25: =AVERAGE('2024'!$G$216:$G$246) -> 5.4703226 | G25: =SUM('2024'!$G$216:$G$246) -> 169.58 | H25: =E25/C25 -> 0.30077227 | I25: =G25*K25 -> 44.806789 | J25: =J24-Tableau37[[#This Row],[Economi theorique]] -> 752.34154 | K25: =SUM('2024'!$D$216:$D$246)/C25 -> 0.26422213
A26: Septembre | B26: =AVERAGE('2024'!$C$247:$C$276) -> 9.8856667 | C26: =SUM('2024'!$C$247:$C$276) -> 296.57 | D26: =AVERAGE('2024'!$F$247:$F$276) -> 3.001 | E26: =SUM('2024'!$F$247:$F$276) -> 90.03 | F26: =AVERAGE('2024'!$G$247:$G$276) -> 3.5243333 | G26: =SUM('2024'!$G$247:$G$276) -> 105.73 | H26: =E26/C26 -> 0.30357083 | I26: =G26*K26 -> 27.81843 | J26: =J25-Tableau37[[#This Row],[Economi theorique]] -> 724.52311 | K26: =SUM('2024'!$D$247:$D$276)/C26 -> 0.2631082
A27: Octobre | B27: =AVERAGE('2024'!$C$277:$C$307) -> 8.3187097 | C27: =SUM('2024'!$C$277:$C$307) -> 257.88 | D27: =AVERAGE('2024'!$F$277:$F$307) -> 2.4467742 | E27: =SUM('2024'!$F$277:$F$307) -> 75.85 | F27: =AVERAGE('2024'!$G$277:$G$307) -> 6.2090323 | G27: =SUM('2024'!$G$277:$G$307) -> 192.48 | H27: =E27/C27 -> 0.29412905 | I27: =G27*K27 -> 47.358678 | J27: =J26-Tableau37[[#This Row],[Economi theorique]]+Kit_Solaire!G26 -> 5689.1644 | K27: =SUM('2024'!$D$277:$D$307)/C27 -> 0.24604467
A28: Novembre | B28: =AVERAGE('2024'!$C$308:$C$337) -> 8.664 | C28: =SUM('2024'!$C$308:$C$337) -> 259.92 | D28: =AVERAGE('2024'!$F$308:$F$337) -> 2.5293333 | E28: =SUM('2024'!$F$308:$F$337) -> 75.88 | F28: =AVERAGE('2024'!$G$308:$G$337) -> 8.7926667 | G28: =SUM('2024'!$G$308:$G$337) -> 263.78 | H28: =E28/C28 -> 0.29193598 | I28: =G28*K28 -> 64.828664 | J28: =J27-Tableau37[[#This Row],[Economi theorique]]+Kit_Solaire!G28 -> 5624.3358 | K28: =SUM('2024'!$D$308:$D$337)/C28 -> 0.24576793
A29: Décembre | B29: =AVERAGE('2024'!$C$338:$C$368) -> 13.239677 | C29: =SUM('2024'!$C$338:$C$368) -> 410.43 | D29: =AVERAGE('2024'!$F$338:$F$368) -> 3.7325806 | E29: =SUM('2024'!$F$338:$F$368) -> 115.71 | F29: =AVERAGE('2024'!$G$338:$G$368) -> 5.1825806 | G29: =SUM('2024'!$G$338:$G$368) -> 160.66 | H29: =E29/C29 -> 0.28192384 | I29: =G29*K29 -> 40.439989 | J29: =J28-Tableau37[[#This Row],[Economi theorique]]+Kit_Solaire!G29 -> 5583.8958 | K29: =SUM('2024'!$D$338:$D$368)/C29 -> 0.25171162
B30: KWH J | C30: KWH Tt | D30: Moy/Mois | E30: Total | G30: Total | M30: Solaire utiliser | N30: eco
B31: =C31/366 -> 10.657705 | C31: =C18+C19+C20+C21+C22+C23+C24+C25+C26+C27+C28+C29 -> 3900.72 | D31: =E31/12 -> 93.23 | E31: =SUM(Tableau37[Total €]) -> 1118.76 | G31: =SUM(Tableau37[Total Prod]) -> 1709.17 | M31: =G31-Kit_Solaire!I11 -> 1203.17 | N31: =M31*Kit_Solaire!J11 -> 299.96011
A33: 2025 | B33: KWH Moyenne jour | C33: KWH Total | D33: Moyenne Jour € | E33: Total € | F33: Production Solaire /KWH Moyenne Jour | G33: Total Prod | H33: Prix du KWH Conso+Abo/KWH | I33: Economi theorique | J33: Reste a amortire | K33: Prix du KWH Sans abonement Prix Econmiser du KWH Solaire Produit
A34: Janvier | B34: =AVERAGE('2025'!$C$2:$C$32) -> 13.050323 | C34: =SUM('2025'!C2:C32) -> 404.56 | D34: =AVERAGE('2025'!$F$2:$F$32) -> 3.6867742 | E34: =SUM('2025'!F2:F32) -> 114.29 | F34: =AVERAGE('2025'!$I$2:$I$32) -> 6.3606452 | G34: =SUM('2025'!I2:I32) -> 197.18 | H34: =E34/C34 -> 0.28250445 | I34: =G34*K34 -> 49.056177 | J34: =Kit_Solaire!L26-(Kit_Solaire!D10+Kit_Solaire!D11)-Tableau378[[#This Row],[Economi theorique]] -> 5671.4812 | K34: =SUM('2025'!$D$2:$D$32)/C34 -> 0.24878881
A35: Fevrier | B35: =AVERAGE('2025'!$C$33:$C$60) -> 9.6325 | C35: =SUM('2025'!C33:C60) -> 269.71 | D35: =AVERAGE('2025'!$F$33:$F$60) -> 2.8228571 | E35: =SUM('2025'!F33:F60) -> 79.04 | F35: =AVERAGE('2025'!$I$33:$I$60) -> 10.989643 | G35: =SUM('2025'!I33:I60) -> 307.71 | H35: =E35/C35 -> 0.2930555 | I35: =G35*K35 -> 76.120319 | J35: =J34-I35 -> 5595.3609 | K35: =SUM('2025'!$D$33:$D$60)/C35 -> 0.24737681
A36: Mars | B36: =AVERAGE('2025'!$C$61:$C$91) -> 8.0583871 | C36: =SUM('2025'!C61:C91) -> 249.81 | D36: =AVERAGE('2025'!$F$61:$F$91) -> 2.33 | E36: =SUM('2025'!F61:F91) -> 72.23 | F36: =AVERAGE('2025'!$I$61:$I$91) -> 13.615806 | G36: =SUM('2025'!I61:I91) -> 422.09 | H36: =E36/C36 -> 0.28913975 | I36: =G36*K36 -> 98.99625 | J36: =J35-I36 -> 5496.3647 | K36: =SUM('2025'!$D$61:$D$91)/C36 -> 0.23453825
A37: Avril | B37: =AVERAGE('2025'!$C$92:$C$121) -> 5.138 | C37: =SUM('2025'!C92:C121) -> 154.14 | D37: =AVERAGE('2025'!$F$92:$F$121) -> 1.8066667 | E37: =SUM('2025'!F92:F121) -> 54.2 | F37: =AVERAGE('2025'!$I$92:$I$121) -> 17.836667 | G37: =SUM('2025'!I92:I121) -> 535.1 | H37: =E37/C37 -> 0.35162839 | I37: =G37*K37 -> 142.3323 | J37: =J36-I37 -> 5354.0324 | K37: =SUM('2025'!$D$92:$D$121)/C37 -> 0.26599196
A38: Mai | B38: =AVERAGE('2025'!$C$122:$C$152) -> 5.0219355 | C38: =SUM('2025'!C122:C152) -> 155.68 | D38: =AVERAGE('2025'!$F$122:$F$152) -> 1.7867742 | E38: =SUM('2025'!F122:F152) -> 55.39 | F38: =AVERAGE('2025'!$I$122:$I$152) -> 19.824516 | G38: =SUM('2025'!I122:I152) -> 614.56 | H38: =E38/C38 -> 0.35579394 | I38: =G38*K38 -> 164.81166 | J38: =J37-I38 -> 5189.2207 | K38: =SUM('2025'!$D$122:$D$152)/C38 -> 0.26817831
A39: Juin | B39: =AVERAGE('2025'!$C$153:$C$182) -> 5.592 | C39: =SUM('2025'!C153:C182) -> 167.76 | D39: =AVERAGE('2025'!$F$153:$F$182) -> 1.9153333 | E39: =SUM('2025'!F153:F182) -> 57.46 | F39: =AVERAGE('2025'!$I$153:$I$182) -> 21.814667 | G39: =SUM('2025'!I153:I182) -> 654.44 | H39: =E39/C39 -> 0.34251311 | I39: =G39*K39 -> 172.66043 | J39: =J38-I39 -> 5016.5603 | K39: =SUM('2025'!$D$153:$D$182)/C39 -> 0.26382928
A40: Juillet | B40: =AVERAGE('2025'!$C$183:$C$213) -> 4.2358065 | C40: =SUM('2025'!C183:C213) -> 131.31 | D40: =AVERAGE('2025'!$F$183:$F$213) -> 1.5529032 | E40: =SUM('2025'!F183:F213) -> 48.14 | F40: =AVERAGE('2025'!$I$183:$I$213) -> 20.122258 | G40: =SUM('2025'!I183:I213) -> 623.79 | H40: =E40/C40 -> 0.36661336 | I40: =G40*K40 -> 163.89273 | J40: =J39-I40 -> 4852.6675 | K40: =SUM('2025'!$D$183:$D$213)/C40 -> 0.26273703
A41: Août | B41: =AVERAGE('2025'!$C$214:$C$244) -> 7.9406452 | C41: =SUM('2025'!C214:C244) -> 246.16 | D41: =AVERAGE('2025'!$F$214:$F$244) -> 2.6358065 | E41: =SUM('2025'!F214:F244) -> 81.71 | F41: =AVERAGE('2025'!$I$214:$I$244) -> 18.965161 | G41: =SUM('2025'!I214:I244) -> 587.92 | H41: =E41/C41 -> 0.33193858 | I41: =G41*K41 -> 162.57603 | J41: =J40-I41 -> 4690.0915 | K41: =SUM('2025'!$D$214:$D$244)/C41 -> 0.27652746
A42: Septembre | B42: =AVERAGE('2025'!$C$245:$C$274) -> 5.0663333 | C42: =SUM('2025'!C245:C274) -> 151.99 | D42: =AVERAGE('2025'!$F$245:$F$274) -> 1.8816667 | E42: =SUM('2025'!F245:F274) -> 56.45 | F42: =AVERAGE('2025'!$I$245:$I$274) -> 14.692 | G42: =SUM('2025'!I245:I274) -> 440.76 | H42: =E42/C42 -> 0.37140601 | I42: =G42*K42 -> 125.42187 | J42: =J41-I42 -> 4564.6696 | K42: =SUM('2025'!$D$245:$D$274)/C42 -> 0.28455819
...

Sheet 2026
A1: Jour | B1: Date | C1: KWH | D1: Conso € | E1: Abonnement € | F1: Total €/J | G1: Prod Solaire /KWH Cab | H1: Prod Solaire /KWH Maison | I1: Prod Solaire Total
A2: Jeudi | B2: 46023 | C2: 10.2 | D2: =Tableau9[[#This Row],[Total €/J]]-Tableau9[[#This Row],[Abonnement €]] -> 2.76 | E2: 0.44 | F2: 3.2 | G2: 1.63 | H2: 6.73 | I2: =Tableau9[[#This Row],[Prod Solaire /KWH Maison]]+Tableau9[[#This Row],[Prod Solaire /KWH Cab]] -> 8.36
A3: Vendredi | B3: 46024 | C3: 9.66 | D3: =Tableau9[[#This Row],[Total €/J]]-Tableau9[[#This Row],[Abonnement €]] -> 2.72 | E3: 0.44 | F3: 3.16 | G3: 1.2 | H3: 6.33 | I3: =Tableau9[[#This Row],[Prod Solaire /KWH Maison]]+Tableau9[[#This Row],[Prod Solaire /KWH Cab]] -> 7.53
A4: Samedi | B4: 46025 | C4: 12.64 | D4: =Tableau9[[#This Row],[Total €/J]]-Tableau9[[#This Row],[Abonnement €]] -> 3.66 | E4: 0.44 | F4: 4.1 | G4: 0.86 | H4: 3.76 | I4: =Tableau9[[#This Row],[Prod Solaire /KWH Maison]]+Tableau9[[#This Row],[Prod Solaire /KWH Cab]] -> 4.62
A5: Dimanche | B5: 46026 | C5: 11.84 | D5: =Tableau9[[#This Row],[Total €/J]]-Tableau9[[#This Row],[Abonnement €]] -> 3.52 | E5: 0.44 | F5: 3.96 | G5: 1.35 | H5: 6.47 | I5: =Tableau9[[#This Row],[Prod Solaire /KWH Maison]]+Tableau9[[#This Row],[Prod Solaire /KWH Cab]] -> 7.82
A6: Lundi | B6: 46027 | C6: 11.75 | D6: =Tableau9[[#This Row],[Total €/J]]-Tableau9[[#This Row],[Abonnement €]] -> 3.43 | E6: 0.44 | F6: 3.87 | G6: 0.41 | H6: 1.09 | I6: =Tableau9[[#This Row],[Prod Solaire /KWH Maison]]+Tableau9[[#This Row],[Prod Solaire /KWH Cab]] -> 1.5
A7: Mardi | B7: 46028 | C7: 11.37 | D7: =Tableau9[[#This Row],[Total €/J]]-Tableau9[[#This Row],[Abonnement €]] -> 3.24 | E7: 0.44 | F7: 3.68 | G7: 1.29 | H7: 4.79 | I7: =Tableau9[[#This Row],[Prod Solaire /KWH Maison]]+Tableau9[[#This Row],[Prod Solaire /KWH Cab]] -> 6.08
A8: Mercredi | B8: 46029 | C8: 10.4 | D8: =Tableau9[[#This Row],[Total €/J]]-Tableau9[[#This Row],[Abonnement €]] -> 2.86 | E8: 0.44 | F8: 3.3 | G8: 0.86 | H8: 3.33 | I8: =Tableau9[[#This Row],[Prod Solaire /KWH Maison]]+Tableau9[[#This Row],[Prod Solaire /KWH Cab]] -> 4.19
A9: Jeudi | B9: 46030 | C9: 17.43 | D9: =Tableau9[[#This Row],[Total €/J]]-Tableau9[[#This Row],[Abonnement €]] -> 4.93 | E9: 0.44 | F9: 5.37 | G9: 0.49 | H9: 1.29 | I9: =Tableau9[[#This Row],[Prod Solaire /KWH Maison]]+Tableau9[[#This Row],[Prod Solaire /KWH Cab]] -> 1.78
A10: Vendredi | B10: 46031 | C10: 13.97 | D10: =Tableau9[[#This Row],[Total €/J]]-Tableau9[[#This Row],[Abonnement €]] -> 4.05 | E10: 0.44 | F10: 4.49 | G10: 0.44 | H10: 1.17 | I10: =Tableau9[[#This Row],[Prod Solaire /KWH Maison]]+Tableau9[[#This Row],[Prod Solaire /KWH Cab]] -> 1.61
A11: Samedi | B11: 46032 | C11: 18.04 | D11: =Tableau9[[#This Row],[Total €/J]]-Tableau9[[#This Row],[Abonnement €]] -> 5.37 | E11: 0.44 | F11: 5.81 | G11: 1.02 | H11: 3.27 | I11: =Tableau9[[#This Row],[Prod Solaire /KWH Maison]]+Tableau9[[#This Row],[Prod Solaire /KWH Cab]] -> 4.29
A12: Dimanche | B12: 46033 | C12: 7.91 | D12: =Tableau9[[#This Row],[Total €/J]]-Tableau9[[#This Row],[Abonnement €]] -> 2.31 | E12: 0.44 | F12: 2.75 | G12: 1.61 | H12: 6.47 | I12: =Tableau9[[#This Row],[Prod Solaire /KWH Maison]]+Tableau9[[#This Row],[Prod Solaire /KWH Cab]] -> 8.08
A13: Lundi | B13: 46034 | C13: 15.53 | D13: =Tableau9[[#This Row],[Total €/J]]-Tableau9[[#This Row],[Abonnement €]] -> 4.53 | E13: 0.44 | F13: 4.97 | G13: 1.2 | H13: 3.54 | I13: =Tableau9[[#This Row],[Prod Solaire /KWH Maison]]+Tableau9[[#This Row],[Prod Solaire /KWH Cab]] -> 4.74
... A270: Samedi | B270: 46291 | C270: 3.52 | D270: =Tableau9[[#This Row],[Total €/J]]-Tableau9[[#This Row],[Abonnement €]] -> 0.94 | E270: 0.44 | F270: 1.38 | G270: 4.63 | H270: 13 | I270: =Tableau9[[#This Row],[Prod Solaire /KWH Maison]]+Tableau9[[#This Row],[Prod Solaire /KWH Cab]] -> 17.63
A271: Dimanche | B271: 46292
A272: Lundi | B272: 46293
A273: Mardi | B273: 46294
A274: Mercredi | B274: 46295
A275: Jeudi | B275: 46296
A276: Vendredi | B276: 46297
A277: Samedi | B277: 46298
A278: Dimanche | B278: 46299
A279: Lundi | B279: 46300
A280: Mardi | B280: 46301
A281: Mercredi | B281: 46302
A282: Jeudi | B282: 46303
... A366: Jeudi | B366: 46387

Sheet 2025
A1: Jour | B1: Date | C1: KWH | D1: Conso € | E1: Abonnement € | F1: Total €/J | G1: Prod Solaire /KWH Cab | H1: Prod Solaire /KWH Maison | I1: Prod Solaire Total
A2: Mercredi | B2: 45658 | C2: 11.94 | D2: =Tableau5[[#This Row],[Total €/J]]-Tableau5[[#This Row],[Abonnement €]] -> 2.93 | E2: 0.44 | F2: 3.37 | G2: 1.53 | H2: 8.04 | I2: =Tableau5[[#This Row],[Prod Solaire /KWH Maison]]+Tableau5[[#This Row],[Prod Solaire /KWH Cab]] -> 9.57
A3: Jeudi | B3: 45659 | C3: 19.77 | D3: =Tableau5[[#This Row],[Total €/J]]-Tableau5[[#This Row],[Abonnement €]] -> 5.11 | E3: 0.44 | F3: 5.55 | G3: 0.98 | H3: 3.28 | I3: =Tableau5[[#This Row],[Prod Solaire /KWH Maison]]+Tableau5[[#This Row],[Prod Solaire /KWH Cab]] -> 4.26
A4: Vendredi | B4: 45660 | C4: 13.3 | D4: =Tableau5[[#This Row],[Total €/J]]-Tableau5[[#This Row],[Abonnement €]] -> 3.33 | E4: 0.44 | F4: 3.77 | G4: 0.67 | H4: 1.81 | I4: =Tableau5[[#This Row],[Prod Solaire /KWH Maison]]+Tableau5[[#This Row],[Prod Solaire /KWH Cab]] -> 2.48
A5: Samedi | B5: 45661 | C5: 9.84 | D5: =Tableau5[[#This Row],[Total €/J]]-Tableau5[[#This Row],[Abonnement €]] -> 2.45 | E5: 0.44 | F5: 2.89 | G5: 0.3 | H5: 0.79 | I5: =Tableau5[[#This Row],[Prod Solaire /KWH Maison]]+Tableau5[[#This Row],[Prod Solaire /KWH Cab]] -> 1.09
A6: Dimanche | B6: 45662 | C6: 12.71 | D6: =Tableau5[[#This Row],[Total €/J]]-Tableau5[[#This Row],[Abonnement €]] -> 3.13 | E6: 0.44 | F6: 3.57 | G6: 1.05 | H6: 3.25 | I6: =Tableau5[[#This Row],[Prod Solaire /KWH Maison]]+Tableau5[[#This Row],[Prod Solaire /KWH Cab]] -> 4.3
A7: Lundi | B7: 45663 | C7: 10.68 | D7: =Tableau5[[#This Row],[Total €/J]]-Tableau5[[#This Row],[Abonnement €]] -> 2.62 | E7: 0.44 | F7: 3.06 | G7: 0.62 | H7: 2.48 | I7: =Tableau5[[#This Row],[Prod Solaire /KWH Maison]]+Tableau5[[#This Row],[Prod Solaire /KWH Cab]] -> 3.1
A8: Mardi | B8: 45664 | C8: 11.16 | D8: =Tableau5[[#This Row],[Total €/J]]-Tableau5[[#This Row],[Abonnement €]] -> 2.7 | E8: 0.44 | F8: 3.14 | G8: 1.5 | H8: 4.9 | I8: =Tableau5[[#This Row],[Prod Solaire /KWH Maison]]+Tableau5[[#This Row],[Prod Solaire /KWH Cab]] -> 6.4
A9: Mercredi | B9: 45665 | C9: 15.87 | D9: =Tableau5[[#This Row],[Total €/J]]-Tableau5[[#This Row],[Abonnement €]] -> 4.2 | E9: 0.44 | F9: 4.64 | G9: 1.26 | H9: 5.31 | I9: =Tableau5[[#This Row],[Prod Solaire /KWH Maison]]+Tableau5[[#This Row],[Prod Solaire /KWH Cab]] -> 6.57
A10: Jeudi | B10: 45666 | C10: 10.62 | D10: =Tableau5[[#This Row],[Total €/J]]-Tableau5[[#This Row],[Abonnement €]] -> 2.65 | E10: 0.44 | F10: 3.09 | G10: 0.88 | H10: 2.46 | I10: =Tableau5[[#This Row],[Prod Solaire /KWH Maison]]+Tableau5[[#This Row],[Prod Solaire /KWH Cab]] -> 3.34
A11: Vendredi | B11: 45667 | C11: 11.95 | D11: =Tableau5[[#This Row],[Total €/J]]-Tableau5[[#This Row],[Abonnement €]] -> 3.03 | E11: 0.44 | F11: 3.47 | G11: 0.66 | H11: 1.75 | I11: =Tableau5[[#This Row],[Prod Solaire /KWH Maison]]+Tableau5[[#This Row],[Prod Solaire /KWH Cab]] -> 2.41
A12: Samedi | B12: 45668 | C12: 19.19 | D12: =Tableau5[[#This Row],[Total €/J]]-Tableau5[[#This Row],[Abonnement €]] -> 4.95 | E12: 0.44 | F12: 5.39 | G12: 0.66 | H12: 2 | I12: =Tableau5[[#This Row],[Prod Solaire /KWH Maison]]+Tableau5[[#This Row],[Prod Solaire /KWH Cab]] -> 2.66
A13: Dimanche | B13: 45669 | C13: 11.12 | D13: =Tableau5[[#This Row],[Total €/J]]-Tableau5[[#This Row],[Abonnement €]] -> 2.74 | E13: 0.44 | F13: 3.18 | G13: 1.85 | H13: 9.5 | I13: =Tableau5[[#This Row],[Prod Solaire /KWH Maison]]+Tableau5[[#This Row],[Prod Solaire /KWH Cab]] -> 11.35
... A98: Lundi | B98: 45754 | C98: 7.66 | D98: =Tableau5[[#This Row],[Total €/J]]-Tableau5[[#This Row],[Abonnement €]] -> 2 | E98: 0.44 | F98: 2.44 | G98: 3.89 | H98: 8.23 | I98: =Tableau5[[#This Row],[Prod Solaire /KWH Maison]]+Tableau5[[#This Row],[Prod Solaire /KWH Cab]] -> 12.12
A99: Mardi | B99: 45755 | C99: 6.8 | D99: =Tableau5[[#This Row],[Total €/J]]-Tableau5[[#This Row],[Abonnement €]] -> 1.65 | E99: 0.44 | F99: 2.09 | G99: 6.09 | H99: 18.6 | I99: =Tableau5[[#This Row],[Prod Solaire /KWH Maison]]+Tableau5[[#This Row],[Prod Solaire /KWH Cab]] -> 24.69 | J99: 4 h en journée
A100: Mercredi | B100: 45756 | C100: 5.33 | D100: =Tableau5[[#This Row],[Total €/J]]-Tableau5[[#This Row],[Abonnement €]] -> 1.25 | E100: 0.44 | F100: 1.69 | G100: 5.38 | H100: 16.2 | I100: =Tableau5[[#This Row],[Prod Solaire /KWH Maison]]+Tableau5[[#This Row],[Prod Solaire /KWH Cab]] -> 21.58
A101: Jeudi | B101: 45757 | C101: 5.27 | D101: =Tableau5[[#This Row],[Total €/J]]-Tableau5[[#This Row],[Abonnement €]] -> 1.31 | E101: 0.44 | F101: 1.75 | G101: 5.78 | H101: 17.7 | I101: =Tableau5[[#This Row],[Prod Solaire /KWH Maison]]+Tableau5[[#This Row],[Prod Solaire /KWH Cab]] -> 23.48
A102: Vendredi | B102: 45758 | C102: 3.96 | D102: =Tableau5[[#This Row],[Total €/J]]-Tableau5[[#This Row],[Abonnement €]] -> 1.02 | E102: 0.44 | F102: 1.46 | G102: 5.11 | H102: 17.4 | I102: =Tableau5[[#This Row],[Prod Solaire /KWH Maison]]+Tableau5[[#This Row],[Prod Solaire /KWH Cab]] -> 22.51
A103: Samedi | B103: 45759 | C103: 4.38 | D103: =Tableau5[[#This Row],[Total €/J]]-Tableau5[[#This Row],[Abonnement €]] -> 1.17 | E103: 0.44 | F103: 1.61 | G103: 5.26 | H103: 17.6 | I103: =Tableau5[[#This Row],[Prod Solaire /KWH Maison]]+Tableau5[[#This Row],[Prod Solaire /KWH Cab]] -> 22.86
A104: Dimanche | B104: 45760 | C104: 6.35 | D104: =Tableau5[[#This Row],[Total €/J]]-Tableau5[[#This Row],[Abonnement €]] -> 1.91 | E104: 0.44 | F104: 2.35 | G104: 2.04 | H104: 5.21 | I104: =Tableau5[[#This Row],[Prod Solaire /KWH Maison]]+Tableau5[[#This Row],[Prod Solaire /KWH Cab]] -> 7.25
A105: Lundi | B105: 45761 | C105: 5.37 | D105: =Tableau5[[#This Row],[Total €/J]]-Tableau5[[#This Row],[Abonnement €]] -> 1.35 | E105: 0.44 | F105: 1.79 | G105: 3.81 | H105: 12.6 | I105: =Tableau5[[#This Row],[Prod Solaire /KWH Maison]]+Tableau5[[#This Row],[Prod Solaire /KWH Cab]] -> 16.41
A106: Mardi | B106: 45762 | C106: 3.97 | D106: =Tableau5[[#This Row],[Total €/J]]-Tableau5[[#This Row],[Abonnement €]] -> 1.02 | E106: 0.44 | F106: 1.46 | G106: 1.46 | H106: 4.04 | I106: =Tableau5[[#This Row],[Prod Solaire /KWH Maison]]+Tableau5[[#This Row],[Prod Solaire /KWH Cab]] -> 5.5
A107: Mercredi | B107: 45763 | C107: 4.05 | D107: =Tableau5[[#This Row],[Total €/J]]-Tableau5[[#This Row],[Abonnement €]] -> 1.09 | E107: 0.44 | F107: 1.53 | G107: 3.62 | H107: 8.99 | I107: =Tableau5[[#This Row],[Prod Solaire /KWH Maison]]+Tableau5[[#This Row],[Prod Solaire /KWH Cab]] -> 12.61
A108: Jeudi | B108: 45764 | C108: 4.06 | D108: =Tableau5[[#This Row],[Total €/J]]-Tableau5[[#This Row],[Abonnement €]] -> 1.1 | E108: 0.44 | F108: 1.54 | G108: 4.41 | H108: 11.5 | I108: =Tableau5[[#This Row],[Prod Solaire /KWH Maison]]+Tableau5[[#This Row],[Prod Solaire /KWH Cab]] -> 15.91
A109: Vendredi | B109: 45765 | C109: 3.69 | D109: =Tableau5[[#This Row],[Total €/J]]-Tableau5[[#This Row],[Abonnement €]] -> 0.87 | E109: 0.44 | F109: 1.31 | G109: 6.53 | H109: 19.8 | I109: =Tableau5[[#This Row],[Prod Solaire /KWH Maison]]+Tableau5[[#This Row],[Prod Solaire /KWH Cab]] -> 26.33
A110: Samedi | B110: 45766 | C110: 5.89 | D110: =Tableau5[[#This Row],[Total €/J]]-Tableau5[[#This Row],[Abonnement €]] -> 1.61 | E110: 0.44 | F110: 2.05 | G110: 1.61 | H110: 5.88 | I110: =Tableau5[[#This Row],[Prod Solaire /KWH Maison]]+Tableau5[[#This Row],[Prod Solaire /KWH Cab]] -> 7.49
A111: Dimanche | B111: 45767 | C111: 2.45 | D111: =Tableau5[[#This Row],[Total €/J]]-Tableau5[[#This Row],[Abonnement €]] -> 0.66 | E111: 0.44 | F111: 1.1 | G111: 5.52 | H111: 18.4 | I111: =Tableau5[[#This Row],[Prod Solaire /KWH Maison]]+Tableau5[[#This Row],[Prod Solaire /KWH Cab]] -> 23.92
... A115: Jeudi | B115: 45771 | C115: 5.34 | D115: =Tableau5[[#This Row],[Total €/J]]-Tableau5[[#This Row],[Abonnement €]] -> 1.39 | E115: 0.44 | F115: 1.83 | G115: 4.61 | H115: 13.2 | I115: =Tableau5[[#This Row],[Prod Solaire /KWH Maison]]+Tableau5[[#This Row],[Prod Solaire /KWH Cab]] -> 17.81
A116: Vendredi | B116: 45772 | C116: 3.58 | D116: =Tableau5[[#This Row],[Total €/J]]-Tableau5[[#This Row],[Abonnement €]] -> 0.79 | E116: 0.44 | F116: 1.23 | G116: 6.68 | H116: 20.1 | I116: =Tableau5[[#This Row],[Prod Solaire /KWH Maison]]+Tableau5[[#This Row],[Prod Solaire /KWH Cab]] -> 26.78 | J116: Activation picine 6h
A117: Samedi | B117: 45773 | C117: 5.22 | D117: =Tableau5[[#This Row],[Total €/J]]-Tableau5[[#This Row],[Abonnement €]] -> 1.42 | E117: 0.44 | F117: 1.86 | G117: 3.07 | H117: 8.14 | I117: =Tableau5[[#This Row],[Prod Solaire /KWH Maison]]+Tableau5[[#This Row],[Prod Solaire /KWH Cab]] -> 11.21
A118: Dimanche | B118: 45774 | C118: 4.46 | D118: =Tableau5[[#This Row],[Total €/J]]-Tableau5[[#This Row],[Abonnement €]] -> 1.29 | E118: 0.44 | F118: 1.73 | G118: 3.91 | H118: 8.92 | I118: =Tableau5[[#This Row],[Prod Solaire /KWH Maison]]+Tableau5[[#This Row],[Prod Solaire /KWH Cab]] -> 12.83
A119: Lundi | B119: 45775 | C119: 4.36 | D119: =Tableau5[[#This Row],[Total €/J]]-Tableau5[[#This Row],[Abonnement €]] -> 1.25 | E119: 0.44 | F119: 1.69 | G119: 5.43 | H119: 16.2 | I119: =Tableau5[[#This Row],[Prod Solaire /KWH Maison]]+Tableau5[[#This Row],[Prod Solaire /KWH Cab]] -> 21.63
A120: Mardi | B120: 45776 | C120: 3.39 | D120: =Tableau5[[#This Row],[Total €/J]]-Tableau5[[#This Row],[Abonnement €]] -> 0.95 | E120: 0.44 | F120: 1.39 | G120: 6.76 | H120: 20.3 | I120: =Tableau5[[#This Row],[Prod Solaire /KWH Maison]]+Tableau5[[#This Row],[Prod Solaire /KWH Cab]] -> 27.06 | J120: 7h
A121: Mercredi | B121: 45777 | C121: 5.05 | D121: =Tableau5[[#This Row],[Total €/J]]-Tableau5[[#This Row],[Abonnement €]] -> 1.34 | E121: 0.44 | F121: 1.78 | G121: 6.78 | H121: 20.4 | I121: =Tableau5[[#This Row],[Prod Solaire /KWH Maison]]+Tableau5[[#This Row],[Prod Solaire /KWH Cab]] -> 27.18
A122: Jeudi | B122: 45778 | C122: 4.83 | D122: =Tableau5[[#This Row],[Total €/J]]-Tableau5[[#This Row],[Abonnement €]] -> 1.06 | E122: 0.44 | F122: 1.5 | G122: 5.68 | H122: 18.5 | I122: =Tableau5[[#This Row],[Prod Solaire /KWH Maison]]+Tableau5[[#This Row],[Prod Solaire /KWH Cab]] -> 24.18
A123: Vendredi | B123: 45779 | C123: 3.76 | D123: =Tableau5[[#This Row],[Total €/J]]-Tableau5[[#This Row],[Abonnement €]] -> 0.7 | E123: 0.44 | F123: 1.14 | G123: 4.66 | H123: 14.5 | I123: =Tableau5[[#This Row],[Prod Solaire /KWH Maison]]+Tableau5[[#This Row],[Prod Solaire /KWH Cab]] -> 19.16
A124: Samedi | B124: 45780 | C124: 3.16 | D124: =Tableau5[[#This Row],[Total €/J]]-Tableau5[[#This Row],[Abonnement €]] -> 0.83 | E124: 0.44 | F124: 1.27 | G124: 5.31 | H124: 17.2 | I124: =Tableau5[[#This Row],[Prod Solaire /KWH Maison]]+Tableau5[[#This Row],[Prod Solaire /KWH Cab]] -> 22.51
A125: Dimanche | B125: 45781 | C125: 6.69 | D125: =Tableau5[[#This Row],[Total €/J]]-Tableau5[[#This Row],[Abonnement €]] -> 1.94 | E125: 0.44 | F125: 2.38 | G125: 1.52 | H125: 4.27 | I125: =Tableau5[[#This Row],[Prod Solaire /KWH Maison]]+Tableau5[[#This Row],[Prod Solaire /KWH Cab]] -> 5.79
A126: Lundi | B126: 45782 | C126: 4.94 | D126: =Tableau5[[#This Row],[Total €/J]]-Tableau5[[#This Row],[Abonnement €]] -> 1.32 | E126: 0.44 | F126: 1.76 | G126: 3.71 | H126: 9.62 | I126: =Tableau5[[#This Row],[Prod Solaire /KWH Maison]]+Tableau5[[#This Row],[Prod Solaire /KWH Cab]] -> 13.33
A127: Mardi | B127: 45783 | C127: 7.87 | D127: =Tableau5[[#This Row],[Total €/J]]-Tableau5[[#This Row],[Abonnement €]] -> 2.14 | E127: 0.44 | F127: 2.58 | G127: 1.79 | H127: 5.04 | I127: =Tableau5[[#This Row],[Prod Solaire /KWH Maison]]+Tableau5[[#This Row],[Prod Solaire /KWH Cab]] -> 6.83
...

Sheet 2024
A2: Jour | B2: Date | C2: KWH | D2: Conso € | E2: Abonnement € | F2: Total €/J | G2: Production Solaire /KWH | H2: Colonne1
A3: Lundi | B3: 45292 | C3: 17.49 | D3: =Tableau13[[#This Row],[Total €/J]]-Tableau13[[#This Row],[Abonnement €]] -> 3.6 | E3: 0.4 | F3: 4 | G3: 1
A4: Mardi | B4: 45293 | C4: 12.73 | D4: =Tableau13[[#This Row],[Total €/J]]-Tableau13[[#This Row],[Abonnement €]] -> 2.56 | E4: 0.4 | F4: 2.96 | G4: 0.86
A5: Mercredi | B5: 45294 | C5: 13.78 | D5: =Tableau13[[#This Row],[Total €/J]]-Tableau13[[#This Row],[Abonnement €]] -> 2.88 | E5: 0.4 | F5: 3.28 | G5: 0.61
A6: jeudi | B6: 45295 | C6: 8.5 | D6: =Tableau13[[#This Row],[Total €/J]]-Tableau13[[#This Row],[Abonnement €]] -> 1.63 | E6: 0.4 | F6: 2.03 | G6: 1.67
A7: vendredi | B7: 45296 | C7: 12.08 | D7: =Tableau13[[#This Row],[Total €/J]]-Tableau13[[#This Row],[Abonnement €]] -> 2.46 | E7: 0.4 | F7: 2.86 | G7: 0.53
A8: Samedi | B8: 45297 | C8: 27.67 | D8: =Tableau13[[#This Row],[Total €/J]]-Tableau13[[#This Row],[Abonnement €]] -> 6.08 | E8: 0.4 | F8: 6.48 | G8: 0.6
A9: Dimanche | B9: 45298 | C9: 13.73 | D9: =Tableau13[[#This Row],[Total €/J]]-Tableau13[[#This Row],[Abonnement €]] -> 2.91 | E9: 0.4 | F9: 3.31 | G9: 0.5
A10: Lundi | B10: 45299 | C10: 10.27 | D10: =Tableau13[[#This Row],[Total €/J]]-Tableau13[[#This Row],[Abonnement €]] -> 2.01 | E10: 0.4 | F10: 2.41 | G10: 0.59
A11: Mardi | B11: 45300 | C11: 12.21 | D11: =Tableau13[[#This Row],[Total €/J]]-Tableau13[[#This Row],[Abonnement €]] -> 2.47 | E11: 0.4 | F11: 2.87 | G11: 1.88
A12: Mercredi | B12: 45301 | C12: 18.17 | D12: =Tableau13[[#This Row],[Total €/J]]-Tableau13[[#This Row],[Abonnement €]] -> 3.52 | E12: 0.4 | F12: 3.92 | G12: 0.8
A13: Jeudi | B13: 45302 | C13: 14.64 | D13: =Tableau13[[#This Row],[Total €/J]]-Tableau13[[#This Row],[Abonnement €]] -> 2.98 | E13: 0.4 | F13: 3.38 | G13: 0.13
A14: Vendredi | B14: 45303 | C14: 15.88 | D14: =Tableau13[[#This Row],[Total €/J]]-Tableau13[[#This Row],[Abonnement €]] -> 3.28 | E14: 0.4 | F14: 3.68 | G14: 0.29
... A103: Mercredi | B103: 45392 | C103: 7.93 | D103: =Tableau13[[#This Row],[Total €/J]]-Tableau13[[#This Row],[Abonnement €]] -> 1.82 | E103: 0.4 | F103: 2.22 | G103: 4.92
A104: Jeudi | B104: 45393 | C104: 6.72 | D104: =Tableau13[[#This Row],[Total €/J]]-Tableau13[[#This Row],[Abonnement €]] -> 1.57 | E104: 0.4 | F104: 1.97 | G104: 6 | H104: Activation picine 8h
A105: Vendredi | B105: 45394 | C105: 9.89 | D105: =Tableau13[[#This Row],[Total €/J]]-Tableau13[[#This Row],[Abonnement €]] -> 2.39 | E105: 0.4 | F105: 2.79 | G105: 6.24 | H105: 9h
A106: Samedi | B106: 45395 | C106: 5.74 | D106: =Tableau13[[#This Row],[Total €/J]]-Tableau13[[#This Row],[Abonnement €]] -> 1.37 | E106: 0.4 | F106: 1.77 | G106: 6.14
A107: Dimanche | B107: 45396 | C107: 10.53 | D107: =Tableau13[[#This Row],[Total €/J]]-Tableau13[[#This Row],[Abonnement €]] -> 2.92 | E107: 0.4 | F107: 3.32 | G107: 5.98
A108: Lundi | B108: 45397 | C108: 9.5 | D108: =Tableau13[[#This Row],[Total €/J]]-Tableau13[[#This Row],[Abonnement €]] -> 2.5 | E108: 0.4 | F108: 2.9 | G108: 2.22
A109: Mardi | B109: 45398 | C109: 8.13 | D109: =Tableau13[[#This Row],[Total €/J]]-Tableau13[[#This Row],[Abonnement €]] -> 2.03 | E109: 0.4 | F109: 2.43 | G109: 4.74
A110: Mercredi | B110: 45399 | C110: 10.65 | D110: =Tableau13[[#This Row],[Total €/J]]-Tableau13[[#This Row],[Abonnement €]] -> 2.77 | E110: 0.4 | F110: 3.17 | G110: 3.52 | H110: 7h
A111: Jeudi | B111: 45400 | C111: 5.96 | D111: =Tableau13[[#This Row],[Total €/J]]-Tableau13[[#This Row],[Abonnement €]] -> 1.52 | E111: 0.4 | F111: 1.92 | G111: 4.71
A112: Vendredi | B112: 45401 | C112: 7.54 | D112: =Tableau13[[#This Row],[Total €/J]]-Tableau13[[#This Row],[Abonnement €]] -> 1.87 | E112: 0.4 | F112: 2.27 | G112: 6.7
A113: Samedi | B113: 45402 | C113: 7.48 | D113: =Tableau13[[#This Row],[Total €/J]]-Tableau13[[#This Row],[Abonnement €]] -> 1.85 | E113: 0.4 | F113: 2.25 | G113: 6.91
A114: Dimanche | B114: 45403 | C114: 8.19 | D114: =Tableau13[[#This Row],[Total €/J]]-Tableau13[[#This Row],[Abonnement €]] -> 2.21 | E114: 0.4 | F114: 2.61 | G114: 6.71
A115: Lundi | B115: 45404 | C115: 8.88 | D115: =Tableau13[[#This Row],[Total €/J]]-Tableau13[[#This Row],[Abonnement €]] -> 2.21 | E115: 0.4 | F115: 2.61 | G115: 5.16
A116: Mardi | B116: 45405 | C116: 8 | D116: =Tableau13[[#This Row],[Total €/J]]-Tableau13[[#This Row],[Abonnement €]] -> 1.93 | E116: 0.4 | F116: 2.33 | G116: 5.46
A117: Mercredi | B117: 45406 | C117: 13.51 | D117: =Tableau13[[#This Row],[Total €/J]]-Tableau13[[#This Row],[Abonnement €]] -> 3.52 | E117: 0.4 | F117: 3.92 | G117: 1.34
A118: Jeudi | B118: 45407 | C118: 10.98 | D118: =Tableau13[[#This Row],[Total €/J]]-Tableau13[[#This Row],[Abonnement €]] -> 2.82 | E118: 0.4 | F118: 3.22 | G118: 3.74
A119: Vendredi | B119: 45408 | C119: 10.3 | D119: =Tableau13[[#This Row],[Total €/J]]-Tableau13[[#This Row],[Abonnement €]] -> 2.63 | E119: 0.4 | F119: 3.03 | G119: 5.25
A120: Samedi | B120: 45409 | C120: 9.53 | D120: =Tableau13[[#This Row],[Total €/J]]-Tableau13[[#This Row],[Abonnement €]] -> 2.47 | E120: 0.4 | F120: 2.87 | G120: 3.58
A121: Dimanche | B121: 45410 | C121: 11.34 | D121: =Tableau13[[#This Row],[Total €/J]]-Tableau13[[#This Row],[Abonnement €]] -> 3.06 | E121: 0.4 | F121: 3.46 | G121: 3.22
A122: Lundi | B122: 45411 | C122: 10.64 | D122: =Tableau13[[#This Row],[Total €/J]]-Tableau13[[#This Row],[Abonnement €]] -> 2.86 | E122: 0.4 | F122: 3.26 | G122: 0.96
... A152: Mercredi | B152: 45441 | C152: 8.13 | D152: =Tableau13[[#This Row],[Total €/J]]-Tableau13[[#This Row],[Abonnement €]] -> 2.11 | E152: 0.4 | F152: 2.51 | G152: 4.39
A153: Jeudi | B153: 45442 | C153: 6.48 | D153: =Tableau13[[#This Row],[Total €/J]]-Tableau13[[#This Row],[Abonnement €]] -> 1.67 | E153: 0.4 | F153: 2.07 | G153: 4.71 | H153: 8H30
A154: Vendredi | B154: 45443 | C154: 9.31 | D154: =Tableau13[[#This Row],[Total €/J]]-Tableau13[[#This Row],[Abonnement €]] -> 2.31 | E154: 0.4 | F154: 2.71 | G154: 4.08
A155: Samedi | B155: 45444 | C155: 21.24 | D155: =Tableau13[[#This Row],[Total €/J]]-Tableau13[[#This Row],[Abonnement €]] -> 5.94 | E155: 0.4 | F155: 6.34 | G155: 4.84
A156: Dimanche | B156: 45445 | C156: 12.41 | D156: =Tableau13[[#This Row],[Total €/J]]-Tableau13[[#This Row],[Abonnement €]] -> 3.27 | E156: 0.4 | F156: 3.67 | G156: 4.51
A157: Lundi | B157: 45446 | C157: 8.1 | D157: =Tableau13[[#This Row],[Total €/J]]-Tableau13[[#This Row],[Abonnement €]] -> 2.07 | E157: 0.4 | F157: 2.47 | G157: 6.6
A158: Mardi | B158: 45447 | C158: 6.84 | D158: =Tableau13[[#This Row],[Total €/J]]-Tableau13[[#This Row],[Abonnement €]] -> 1.85 | E158: 0.4 | F158: 2.25 | G158: 6.89 | H158: 10h
...

Sheet 2023
A2: Jour | B2: Date | C2: KWH | D2: Conso € | E2: Abonnement € | F2: Total €/J | G2: Production Solaire /KWH
A3: Dimanche | B3: 44927 | C3: 13.49 | D3: =3.23-0.43 -> 2.8 | E3: 0.4 | F3: =D3+E3 -> 3.2
A4: Lundi | B4: 44928 | C4: 10.4 | D4: =2.58-0.43 -> 2.15 | E4: 0.4 | F4: =D4+E4 -> 2.55
A5: Mardi | B5: 44929 | C5: 13.45 | D5: =3.22-0.43 -> 2.79 | E5: 0.4 | F5: =D5+E5 -> 3.19
A6: Mercredi | B6: 44930 | C6: 11.75 | D6: =2.86-0.43 -> 2.43 | E6: 0.4 | F6: =D6+E6 -> 2.83
A7: Jeudi | B7: 44931 | C7: 12.88 | D7: =3.1-0.43 -> 2.67 | E7: 0.4 | F7: =D7+E7 -> 3.07
A8: Vendredi | B8: 44932 | C8: 10.7 | D8: =2.64-0.43 -> 2.21 | E8: 0.4 | F8: =D8+E8 -> 2.61
A9: Samedi | B9: 44933 | C9: 21.85 | D9: =4.99-0.43 -> 4.56 | E9: 0.4 | F9: =D9+E9 -> 4.96
A10: Dimanche | B10: 44934 | C10: 13.41 | D10: =3.21-0.43 -> 2.78 | E10: 0.4 | F10: =D10+E10 -> 3.18
A11: Lundi | B11: 44935 | C11: 12.5 | D11: =3.02-0.43 -> 2.59 | E11: 0.4 | F11: =D11+E11 -> 2.99
A12: Mardi | B12: 44936 | C12: 10.25 | D12: =2.55-0.43 -> 2.12 | E12: 0.4 | F12: =D12+E12 -> 2.52
A13: Mercredi | B13: 44937 | C13: 14.02 | D13: =Tableau1[[#This Row],[Total €/J]]-Tableau1[[#This Row],[Abonnement €]] -> 2.94 | E13: 0.4 | F13: 3.34
A14: Jeudi | B14: 44938 | C14: 12.45 | D14: =Tableau1[[#This Row],[Total €/J]]-Tableau1[[#This Row],[Abonnement €]] -> 2.61 | E14: 0.4 | F14: 3.01
A15: Vendredi | B15: 44939 | C15: 19.22 | D15: =Tableau1[[#This Row],[Total €/J]]-Tableau1[[#This Row],[Abonnement €]] -> 4.04 | E15: 0.4 | F15: 4.44
A16: Samedi | B16: 44940 | C16: 14.83 | D16: =Tableau1[[#This Row],[Total €/J]]-Tableau1[[#This Row],[Abonnement €]] -> 3.11 | E16: 0.4 | F16: 3.51
A17: Dimanche | B17: 44941 | C17: 19.21 | D17: =Tableau1[[#This Row],[Total €/J]]-Tableau1[[#This Row],[Abonnement €]] -> 4.04 | E17: 0.4 | F17: 4.44
A18: Lundi | B18: 44942 | C18: 21.48 | D18: =Tableau1[[#This Row],[Total €/J]]-Tableau1[[#This Row],[Abonnement €]] -> 4.51 | E18: 0.4 | F18: 4.91
A19: Mardi | B19: 44943 | C19: 15.35 | D19: =Tableau1[[#This Row],[Total €/J]]-Tableau1[[#This Row],[Abonnement €]] -> 3.22 | E19: 0.4 | F19: 3.62
A20: Mercredi | B20: 44944 | C20: 19.18 | D20: =Tableau1[[#This Row],[Total €/J]]-Tableau1[[#This Row],[Abonnement €]] -> 4.03 | E20: 0.4 | F20: 4.43
A21: Jeudi | B21: 44945 | C21: 19.3 | D21: =Tableau1[[#This Row],[Total €/J]]-Tableau1[[#This Row],[Abonnement €]] -> 4.05 | E21: 0.4 | F21: 4.45
A22: Vendredi | B22: 44946 | C22: 21.66 | D22: =Tableau1[[#This Row],[Total €/J]]-Tableau1[[#This Row],[Abonnement €]] -> 4.55 | E22: 0.4 | F22: 4.95
A23: Samedi | B23: 44947 | C23: 21.46 | D23: =Tableau1[[#This Row],[Total €/J]]-Tableau1[[#This Row],[Abonnement €]] -> 4.51 | E23: 0.4 | F23: 4.91
A24: Dimanche | B24: 44948 | C24: 20.15 | D24: =Tableau1[[#This Row],[Total €/J]]-Tableau1[[#This Row],[Abonnement €]] -> 4.23 | E24: 0.4 | F24: 4.63
... A102: Lundi | B102: 45026 | C102: 8.89 | D102: =Tableau1[[#This Row],[Total €/J]]-Tableau1[[#This Row],[Abonnement €]] -> 1.86 | E102: 0.4 | F102: 2.26
A103: Mardi | B103: 45027 | C103: 14.04 | D103: =Tableau1[[#This Row],[Total €/J]]-Tableau1[[#This Row],[Abonnement €]] -> 2.93 | E103: 0.4 | F103: 3.33 | H103: Activation picine 7h
A104: Mercredi | B104: 45028 | C104: 9.3 | D104: =Tableau1[[#This Row],[Total €/J]]-Tableau1[[#This Row],[Abonnement €]] -> 1.94 | E104: 0.4 | F104: 2.34
A105: Jeudi | B105: 45029 | C105: 10.09 | D105: =Tableau1[[#This Row],[Total €/J]]-Tableau1[[#This Row],[Abonnement €]] -> 2.11 | E105: 0.4 | F105: 2.51
A106: Vendredi | B106: 45030 | C106: 11.98 | D106: =Tableau1[[#This Row],[Total €/J]]-Tableau1[[#This Row],[Abonnement €]] -> 2.5 | E106: 0.4 | F106: 2.9
A107: Samedi | B107: 45031 | C107: 21.08 | D107: =Tableau1[[#This Row],[Total €/J]]-Tableau1[[#This Row],[Abonnement €]] -> 4.4 | E107: 0.4 | F107: 4.8
A108: Dimanche | B108: 45032 | C108: 12.67 | D108: =Tableau1[[#This Row],[Total €/J]]-Tableau1[[#This Row],[Abonnement €]] -> 2.64 | E108: 0.4 | F108: 3.04
A109: Lundi | B109: 45033 | C109: 11.41 | D109: =Tableau1[[#This Row],[Total €/J]]-Tableau1[[#This Row],[Abonnement €]] -> 2.38 | E109: 0.4 | F109: 2.78
A110: Mardi | B110: 45034 | C110: 13.68 | D110: =Tableau1[[#This Row],[Total €/J]]-Tableau1[[#This Row],[Abonnement €]] -> 2.9 | E110: 0.4 | F110: 3.3
A111: Mercredi | B111: 45035 | C111: 13.68 | D111: =Tableau1[[#This Row],[Total €/J]]-Tableau1[[#This Row],[Abonnement €]] -> 2.79 | E111: 0.4 | F111: 3.19
A112: Jeudi | B112: 45036 | C112: 10.3 | D112: =Tableau1[[#This Row],[Total €/J]]-Tableau1[[#This Row],[Abonnement €]] -> 2.13 | E112: 0.4 | F112: 2.53
A113: Vendredi | B113: 45037 | C113: 20.8 | D113: =Tableau1[[#This Row],[Total €/J]]-Tableau1[[#This Row],[Abonnement €]] -> 4.29 | E113: 0.4 | F113: 4.69 | H113: 11h
A114: Samedi | B114: 45038 | C114: 19.53 | D114: =Tableau1[[#This Row],[Total €/J]]-Tableau1[[#This Row],[Abonnement €]] -> 4.03 | E114: 0.4 | F114: 4.43
A115: Dimanche | B115: 45039 | C115: 19.15 | D115: =Tableau1[[#This Row],[Total €/J]]-Tableau1[[#This Row],[Abonnement €]] -> 3.95 | E115: 0.4 | F115: 4.35
A116: Lundi | B116: 45040 | C116: 13.95 | D116: =Tableau1[[#This Row],[Total €/J]]-Tableau1[[#This Row],[Abonnement €]] -> 2.88 | E116: 0.4 | F116: 3.28
A117: Mardi | B117: 45041 | C117: 18.57 | D117: =Tableau1[[#This Row],[Total €/J]]-Tableau1[[#This Row],[Abonnement €]] -> 3.83 | E117: 0.4 | F117: 4.23
A118: Mercredi | B118: 45042 | C118: 18.49 | D118: =Tableau1[[#This Row],[Total €/J]]-Tableau1[[#This Row],[Abonnement €]] -> 3.82 | E118: 0.4 | F118: 4.22
...

Sheet Graf
A1: Année | B1: Janvier | C1: Fevrier | D1: Mars | E1: Avril | F1: Mai | G1: Juin | H1: Juiller | I1: Aout | J1: Septembre | K1: Octobre | L1: Novembre | M1: Decenbre | N1: Année | O1: €/A | P1: KWH/A | Q1: Revente EDF | R1: Coup anuelle | S1: Prix du Kwh Moy | T1: KWH/Moy/M | U1: KWH/Moy/J
A2: 2023 | B2: =Global!C2 -> 541.83 | C2: =Global!C3 -> 447.05 | D2: =Global!C4 -> 417.03 | E2: =Global!C5 -> 406.82 | F2: =Global!C6 -> 637.04 | G2: =Global!C7 -> 302.35 | H2: =Global!C8 -> 353.77 | I2: =Global!C9 -> 387.4 | J2: =Global!C10 -> 338.95 | K2: =Global!C11 -> 314.27 | L2: =Global!C12 -> 366.55 | M2: =Global!C13 -> 443.91 | N2: 2023 | O2: =Global!E15 -> 1183.58 | P2: =Global!C15 -> 4956.97 | Q2: 0 | R2: =O2-Q2 -> 1183.58 | S2: =R2/P2 -> 0.23877086 | T2: =P2/12 -> 413.08083 | U2: =P2/365 -> 13.58074
A3: 2024 | B3: =Global!C18 -> 438.69 | C3: =Global!C19 -> 396.26 | D3: =Global!C20 -> 354.59 | E3: =Global!C21 -> 286.95 | F3: =Global!C22 -> 259.97 | G3: =Global!C23 -> 286.61 | H3: =Global!C24 -> 313.59 | I3: =Global!C25 -> 339.26 | J3: =Global!C26 -> 296.57 | K3: =Global!C27 -> 257.88 | L3: =Global!C28 -> 259.92 | M3: =Global!C29 -> 410.43 | N3: 2024 | O3: =Global!E31 -> 1118.76 | P3: =Global!C31 -> 3900.72 | Q3: 0 | R3: =O3-Q3 -> 1118.76 | S3: =R3/P3 -> 0.28680859 | T3: =P3/12 -> 325.06 | U3: =P3/366 -> 10.657705
A4: 2025 | B4: =Global!C34 -> 404.56 | C4: =Global!C35 -> 269.71 | D4: =Global!C36 -> 249.81 | E4: =Global!C37 -> 154.14 | F4: =Global!C38 -> 155.68 | G4: =Global!C39 -> 167.76 | H4: =Global!C40 -> 131.31 | I4: =Global!C41 -> 246.16 | J4: =Global!C42 -> 151.99 | K4: =Global!C43 -> 205.82 | L4: =Global!C44 -> 322.55 | M4: =Global!C45 -> 360.56 | N4: 2025 | O4: =Global!E47 -> 906.69 | P4: =SUM(B4:M4) -> 2820.05 | Q4: =Kit_Solaire!L12 -> 371.95 | R4: =O4-Q4 -> 534.74 | S4: =R4/P4 -> 0.18962075 | T4: =P4/12 -> 235.00417 | U4: =P4/365 -> 7.7261644
A5: 2026 | B5: =Global!C50 -> 348.45 | C5: =Global!C51 -> 259.3 | D5: =Global!C52 -> 242.69 | E5: =Global!C53 -> 164.38 | F5: =Global!C54 -> 148.12 | G5: =Global!C55 -> 196.12 | H5: =Global!C56 -> 167.51 | I5: =Global!C57 -> 234.42 | J5: =Global!C58 -> 126.71 | N5: 2026 | O5: =Global!E63 -> 639.43 | P5: =Global!C63 -> 1887.7 | Q5: =Kit_Solaire!L13 -> 341.33 | R5: =O5-Q5 -> 298.1 | S5: =Tableau10[[#This Row],[Coup anuelle ]]/Tableau10[[#This Row],[KWH/A]] -> 0.15791704
A6: 2027 | N6: 2027
A7: 2028 | N7: 2028
A8: 2029 | N8: 2029
A9: 2030 | N9: 2030

Sheet EXPORT_SITE
A1: clé | B1: valeur | E1: annee | F1: production_kwh | G1: consommation_kwh | H1: injection_kwh | I1: autoconsommation_kwh | J1: facture_kwh
A2: nom_installation | B2: Maison Albi | E2: 2023 | F2: =Kit_Solaire!E10 -> 904.28 | G2: =Global!C15 -> 4956.97 | H2: =Kit_Solaire!I10 -> 50 | I2: =Tableau11[[#This Row],[production_kwh]]-Tableau11[[#This Row],[injection_kwh]] -> 854.28 | J2: 0
A3: puissance_kwc_Total | B3: =Kit_Solaire!I2 -> 4.11 | E3: 2024 | F3: =Kit_Solaire!E11 -> 1709.17 | G3: =Global!C31 -> 3900.72 | H3: =Kit_Solaire!I11 -> 506 | I3: =Tableau11[[#This Row],[production_kwh]]-Tableau11[[#This Row],[injection_kwh]] -> 1203.17 | J3: 0
A4: nombre_panneaux | B4: 9 | E4: 2025 | F4: =Kit_Solaire!E12 -> 5120.12 | G4: =Global!C47 -> 2820.05 | H4: =Kit_Solaire!I12 -> 2874 | I4: =Tableau11[[#This Row],[production_kwh]]-Tableau11[[#This Row],[injection_kwh]] -> 2246.12 | J4: =Kit_Solaire!O12 -> 2915
A5: Produit_2_date_mise_service | B5: 45582 | E5: 2026 | F5: =Kit_Solaire!E13 -> 4558.98 | G5: =Global!C63 -> 1887.7 | H5: =Kit_Solaire!I13 -> 2608 | I5: =Tableau11[[#This Row],[production_kwh]]-Tableau11[[#This Row],[injection_kwh]] -> 1950.98 | J5: =Kit_Solaire!O13 -> 2675
A6: Produit_1_date_mise_service | B6: 45054 | E6: 2027
A7: cout_installation_Total | B7: =Kit_Solaire!L26 -> 6205.65 | E7: 2028
A8: prix_reference_kwh | B8: =AVERAGE(Kit_Solaire!J10:J17) -> 0.24980167 | E8: 2029
A9: Produit_1_Pan_Sol_PlugAndPlay | B9: =Kit_Solaire!F5 -> 1193.65 | E9: 2030
A10: Produit_2_Pan_Sol_Maison | B10: =Kit_Solaire!G26 -> 5012
A11: Produit_1_puissance_kwc | B11: 1.11
A12: Produit_2_puissance_kwc | B12: 3
A17: indicateur | B17: valeur | E17: Annee | F17: Janvier_kwh | G17: Fevrier_kwh | H17: Mars_kwh | I17: Avril_kwh | J17: Mai_kwh | K17: Juin_kwh | L17: Juiller_kwh | M17: Aout_kwh | N17: Septembre_kwh | O17: Octobre_kwh | P17: Novembre_kwh | Q17: Decenbre_kwh
A18: production_totale | B18: =Global!G15+Global!G31+Global!G47+Global!G63 -> 12292.55 | E18: 2023 | F18: =Graf!B2 -> 541.83 | G18: =Graf!C2 -> 447.05 | H18: =Graf!D2 -> 417.03 | I18: =Graf!E2 -> 406.82 | J18: =Graf!F2 -> 637.04 | K18: =Graf!G2 -> 302.35 | L18: =Graf!H2 -> 353.77 | M18: =Graf!I2 -> 387.4 | ... Q18: =Graf!M2 -> 443.91
A19: consommation_totale | B19: =Graf!P2+Graf!P3+Graf!P4+Graf!P5+Graf!P6+Graf!P7+Graf!P8 -> 13565.44 | E19: 2024 | F19: =Graf!B3 -> 438.69 | G19: =Graf!C3 -> 396.26 | H19: =Graf!D3 -> 354.59 | I19: =Graf!E3 -> 286.95 | J19: =Graf!F3 -> 259.97 | K19: =Graf!G3 -> 286.61 | L19: =Graf!H3 -> 313.59 | M19: =Graf!I3 -> 339.26 | ... Q19: =Graf!M3 -> 410.43
A20: injection_totale | B20: =Kit_Solaire!I18 -> 6038 | E20: 2025 | F20: =Graf!B4 -> 404.56 | G20: =Graf!C4 -> 269.71 | H20: =Graf!D4 -> 249.81 | I20: =Graf!E4 -> 154.14 | J20: =Graf!F4 -> 155.68 | K20: =Graf!G4 -> 167.76 | L20: =Graf!H4 -> 131.31 | M20: =Graf!I4 -> 246.16 | ... Q20: =Graf!M4 -> 360.56
A21: economie_totale | B21: =Kit_Solaire!L2 -> 2316.3827 | E21: 2026 | F21: =Graf!B5 -> 348.45 | G21: =Graf!C5 -> 259.3 | H21: =Graf!D5 -> 242.69 | I21: =Graf!E5 -> 164.38 | J21: =Graf!F5 -> 148.12 | K21: =Graf!G5 -> 196.12 | L21: =Graf!H5 -> 167.51 | M21: =Graf!I5 -> 234.42 | ... Q21: =Graf!M5 -> 0
A22: amortissement_euro | B22: =Kit_Solaire!N2 -> -3889.2673 | E22: 2027
A23: amortissement_pourcent | B23: =B21/B7 -> 0.37326996 | E23: 2028
E24: 2029
E25: 2030

Sheet PARAMETRES_COCKPIT
A1: Cockpit solaire — paramètres & contexte
A2: Clé | B2: Valeur | C2: Unité / format | D2: Source / note
A3: first_full_solar_year | B3: 2025 | C3: année | D3: Première année complète avec les deux installations
A4: plug_power_kwc | B4: 1.11 | C4: kWc | D4: Kit plug-and-play
A5: plug_orientation | B5: Ouest | C5: texte | D5: Contexte utilisateur
A6: plug_service_date | B6: 45054 | C6: date | D6: Classeur / mise en service
A7: plug_role | B7: Compensation initiale de la consommation de la piscine, puis complément de production en fin de journée | C7: texte | D7: Contexte utilisateur
A8: main_power_kwc | B8: 3 | C8: kWc | D8: Installation toiture Kbane / DualSun
A9: main_orientation | B9: Plein sud, légère composante ouest | C9: texte | D9: Contexte utilisateur
A10: main_service_date | B10: 45582 | C10: date | D10: Classeur / mise en service
A11: main_shading_note | B11: Ombre ponctuelle d'un arbre voisin surtout en hiver, environ 10 h à 11 h | C11: texte | D11: Contexte utilisateur
A12: pool_surface_m2_est | B12: 9.89 | C12: m² | D12: Dimensions approximatives 2,30 × 4,30 m
A13: pool_water_depth_m | B13: 1.3 | C13: m | D13: Niveau d'eau utile approximatif
A14: pool_volume_m3_est | B14: 12.857 | C14: m³ | D14: Estimation géométrique, hors formes/parois
A15: pool_pump_power_w | B15: 750 | C15: W | D15: Puissance pompe communiquée
A16: pool_summer_runtime_low_h | B16: 8 | C16: h/j | D16: Filtration typique été : environ 9/10 h → 18 h
A17: pool_summer_runtime_high_h | B17: 9 | C17: h/j | D17: Filtration typique été : environ 9/10 h → 18 h
A18: pool_summer_daily_kwh_low | B18: 6 | C18: kWh/j | D18: Calcul 0,75 kW × 8 h
A19: pool_summer_daily_kwh_high | B19: 6.75 | C19: kWh/j | D19: Calcul 0,75 kW × 9 h
A20: edf_oa_tariff_eur_kwh | B20: 0.1276 | C20: €/kWh | D20: Contrat EDF OA
A21: edf_oa_2025_invoice_start | B21: 45614 | C21: date | D21: Facture EDF OA 2025
A22: edf_oa_2025_invoice_end | B22: 45978 | C22: date | D22: Facture EDF OA 2025
A23: edf_oa_2025_invoice_kwh | B23: 2915 | C23: kWh | D23: Facture EDF OA 2025
A24: edf_oa_2025_invoice_eur | B24: 371.95 | C24: € | D24: Facture EDF OA 2025
A25: note_oa_calendar | B25: La revente facturée suit une période de facturation EDF OA et non strictement l'année civile. | C25: texte | D25: Règle de lecture
A26: note_weather | B26: Température/pluie contextualisent la production mais ne remplacent pas une mesure d'irradiation solaire. | C26: texte | D26: Règle de lecture
A27: note_injection_monthly | B27: Sans injection mensuelle réelle, toute ventilation mensuelle de l'injection est une estimation. | C27: texte | D27: Règle de lecture
